LOCAL_RANK: 0 - CUDA_VISIBLE_DEVICES: [0,1]

  | Name  | Type     | Params | Mode
-------------------------------------------
0 | model | Wang2024 | 2.4 M  | train
-------------------------------------------
2.4 M     Trainable params
0         Non-trainable params
2.4 M     Total params
9.480     Total estimated model params size (MB)
8         Modules in train mode
0         Modules in eval mode
Epoch 1: 100%|███████████████████████████████████████████████████████████████████████████████████████████████████████████████████████████████████████████████████████████████████████████████████████████████████████████████████| 79/79 [00:03<00:00, 25.34it/s, v_num=mtyj]
Validation: |                                                                                                                                                                                                                                          | 0/? [00:00<?, ?it/s]
Exception ignored in: <function _releaseLock at 0x7fd32a02c040>
Traceback (most recent call last):
  File "/felles_gfi/felles_gfi_users/rogui7909/miniforge3/envs/robin/lib/python3.12/logging/__init__.py", line 243, in _releaseLock
    def _releaseLock():

KeyboardInterrupt:
Traceback (most recent call last):
  File "/felles_gfi/felles_gfi_users/rogui7909/miniforge3/envs/robin/lib/python3.12/site-packages/torch/utils/data/dataloader.py", line 1243, in _try_get_data
    data = self._data_queue.get(timeout=timeout)
           ^^^^^^^^^^^^^^^^^^^^^^^^^^^^^^^^^^^^^
  File "/felles_gfi/felles_gfi_users/rogui7909/miniforge3/envs/robin/lib/python3.12/multiprocessing/queues.py", line 114, in get
    raise Empty
_queue.Empty

The above exception was the direct cause of the following exception:

Traceback (most recent call last):
  File "/shared_netapp3_home/home/rogui7909/code/predict_rain_norway/rain_lighting.py", line 218, in <module>
    trainer.fit(model, train_loader, valid_loader)
  File "/felles_gfi/felles_gfi_users/rogui7909/miniforge3/envs/robin/lib/python3.12/site-packages/lightning/pytorch/trainer/trainer.py", line 539, in fit
    call._call_and_handle_interrupt(
  File "/felles_gfi/felles_gfi_users/rogui7909/miniforge3/envs/robin/lib/python3.12/site-packages/lightning/pytorch/trainer/call.py", line 47, in _call_and_handle_interrupt
    return trainer_fn(*args, **kwargs)
           ^^^^^^^^^^^^^^^^^^^^^^^^^^^
  File "/felles_gfi/felles_gfi_users/rogui7909/miniforge3/envs/robin/lib/python3.12/site-packages/lightning/pytorch/trainer/trainer.py", line 575, in _fit_impl
    self._run(model, ckpt_path=ckpt_path)
  File "/felles_gfi/felles_gfi_users/rogui7909/miniforge3/envs/robin/lib/python3.12/site-packages/lightning/pytorch/trainer/trainer.py", line 982, in _run
    results = self._run_stage()
              ^^^^^^^^^^^^^^^^^
  File "/felles_gfi/felles_gfi_users/rogui7909/miniforge3/envs/robin/lib/python3.12/site-packages/lightning/pytorch/trainer/trainer.py", line 1026, in _run_stage
    self.fit_loop.run()
  File "/felles_gfi/felles_gfi_users/rogui7909/miniforge3/envs/robin/lib/python3.12/site-packages/lightning/pytorch/loops/fit_loop.py", line 216, in run
    self.advance()
  File "/felles_gfi/felles_gfi_users/rogui7909/miniforge3/envs/robin/lib/python3.12/site-packages/lightning/pytorch/loops/fit_loop.py", line 455, in advance
    self.epoch_loop.run(self._data_fetcher)
  File "/felles_gfi/felles_gfi_users/rogui7909/miniforge3/envs/robin/lib/python3.12/site-packages/lightning/pytorch/loops/training_epoch_loop.py", line 151, in run
    self.on_advance_end(data_fetcher)
  File "/felles_gfi/felles_gfi_users/rogui7909/miniforge3/envs/robin/lib/python3.12/site-packages/lightning/pytorch/loops/training_epoch_loop.py", line 370, in on_advance_end
    self.val_loop.run()
  File "/felles_gfi/felles_gfi_users/rogui7909/miniforge3/envs/robin/lib/python3.12/site-packages/lightning/pytorch/loops/utilities.py", line 179, in _decorator
    return loop_run(self, *args, **kwargs)
           ^^^^^^^^^^^^^^^^^^^^^^^^^^^^^^^
  File "/felles_gfi/felles_gfi_users/rogui7909/miniforge3/envs/robin/lib/python3.12/site-packages/lightning/pytorch/loops/evaluation_loop.py", line 137, in run
    batch, batch_idx, dataloader_idx = next(data_fetcher)
                                       ^^^^^^^^^^^^^^^^^^
  File "/felles_gfi/felles_gfi_users/rogui7909/miniforge3/envs/robin/lib/python3.12/site-packages/lightning/pytorch/loops/fetchers.py", line 134, in __next__
    batch = super().__next__()
            ^^^^^^^^^^^^^^^^^^
  File "/felles_gfi/felles_gfi_users/rogui7909/miniforge3/envs/robin/lib/python3.12/site-packages/lightning/pytorch/loops/fetchers.py", line 61, in __next__
    batch = next(self.iterator)
            ^^^^^^^^^^^^^^^^^^^
  File "/felles_gfi/felles_gfi_users/rogui7909/miniforge3/envs/robin/lib/python3.12/site-packages/lightning/pytorch/utilities/combined_loader.py", line 341, in __next__
    out = next(self._iterator)
          ^^^^^^^^^^^^^^^^^^^^
  File "/felles_gfi/felles_gfi_users/rogui7909/miniforge3/envs/robin/lib/python3.12/site-packages/lightning/pytorch/utilities/combined_loader.py", line 142, in __next__
    out = next(self.iterators[0])
          ^^^^^^^^^^^^^^^^^^^^^^^
  File "/felles_gfi/felles_gfi_users/rogui7909/miniforge3/envs/robin/lib/python3.12/site-packages/torch/utils/data/dataloader.py", line 701, in __next__
    data = self._next_data()
           ^^^^^^^^^^^^^^^^^
  File "/felles_gfi/felles_gfi_users/rogui7909/miniforge3/envs/robin/lib/python3.12/site-packages/torch/utils/data/dataloader.py", line 1448, in _next_data
    idx, data = self._get_data()
                ^^^^^^^^^^^^^^^^
  File "/felles_gfi/felles_gfi_users/rogui7909/miniforge3/envs/robin/lib/python3.12/site-packages/torch/utils/data/dataloader.py", line 1412, in _get_data
    success, data = self._try_get_data()
                    ^^^^^^^^^^^^^^^^^^^^
  File "/felles_gfi/felles_gfi_users/rogui7909/miniforge3/envs/robin/lib/python3.12/site-packages/torch/utils/data/dataloader.py", line 1256, in _try_get_data
    raise RuntimeError(
RuntimeError: DataLoader worker (pid(s) 46388, 46457, 46616) exited unexpectedly
